Workbook
Name AGICODE: OFFSET([1]Sheet4!$B$4,1,0,COUNTA([1]Sheet4!$B:$B)-1,1)
Name MONTH: OFFSET([1]Sheet4!$J$4,1,0,COUNTA([1]Sheet4!$J:$J)-1,1)
Name NAMEOFPRODUCTS: OFFSET([1]Sheet4!$D$4,1,0,COUNTA([1]Sheet4!$D:$D)-1,1)
Name NameofWH: OFFSET([1]Sheet4!$H$4,1,0,COUNTA([1]Sheet4!$H:$H)-1,1)
Name PACKSIZE: OFFSET([1]Sheet4!$F$4,1,0,COUNTA([1]Sheet4!$F:$F)-1,1)

Sheet Sheet6
B3: EXPIRY ON (MONTH) | C3: AGI Code | D3: Name of Products | E3: Pack Size | F3: Total
B4: 45992 | C4: 69667 | D4: ALIKA 247ZC | E4: 20X50ml | F4: 20
B5: 45992 | C5: 72523 | D5: FASAL TAP | E5: 40X50 ML | F5: 22
B6: 46043 | C6: 82888 | D6: FASAL UP | E6: 10X1 L | F6: 20
B7: 46043 | C7: 82888 | D7: FASAL UP | E7: 10X1 L | F7: 50
B8: 46082 | C8: 69037 | D8: GAYLE 18WP | E8: 30X100 G | F8: 1194
B9: 46082 | C9: 84793 | D9: VESTORIA 20WG | E9: 25X15 G | F9: 1370.625
B10: 46113 | C10: 68508 | D10: FASAL TAP | E10: 30X100 G | F10: 6
B11: 46113 | C11: 72523 | D11: FASAL TAP | E11: 40X50 ML | F11: 1348
B12: 46113 | C12: 82898 | D12: FASAL UP | E12: 10x500 ML | F12: 1145
B13: 46113 | C13: 72523 | D13: FASAL TAP | E13: 40X50 ML | F13: 1886
B14: 46113 | C14: 82888 | D14: FASAL UP | E14: 10X1 L | F14: 330
B15: 46113 | C15: 82898 | D15: FASAL UP | E15: 10x500 ML | F15: 1710
... B57: 46327 | C57: 68508 | D57: FASAL TAP | E57: 30X100 G | F57: 3
B58: Grand Total | F58: 70670.145

Sheet Sheet3
B4: EXPIRY ON (MONTH) | C4: AGI Code | D4: Name of Products | E4: Pack Size | F4: EXPIRY QTY LM | G4: SOLD QTY | H4: EXPIRY QTY CM | I4: Total
B5: 45992 | C5: 72523 | D5: FASAL TAP | E5: 40X50 ML | F5: 3 | G5: 1 | H5: 2 | I5: 4
B6: 45992 | C6: 69667 | D6: ALIKA 247ZC | E6: 20X50ml | F6: 89 | G6: 88 | I6: 1
B7: 45992 | C7: 69667 | D7: ALIKA 247ZC | E7: 20X50ml | F7: 123 | G7: 30 | H7: 19 | I7: 19
B8: 45992 | C8: 72523 | D8: FASAL TAP | E8: 40X50 ML | F8: 0 | G8: 11 | H8: 9 | I8: 18
B9: 46043 | C9: 82888 | D9: FASAL UP | E9: 10X1 L | F9: 7 | G9: 2 | H9: 2 | I9: 20
B10: 46047 | C10: 82888 | D10: FASAL UP | E10: 10X1 L | F10: 0 | G10: -5 | H10: 5 | I10: 50
B11: 46082 | C11: 69037 | D11: GAYLE 18WP | E11: 30X100 G | F11: 253 | G11: 71 | H11: 182 | I11: 546
B12: 46082 | C12: 84793 | D12: VESTORIA 20WG | E12: 25X15 G | F12: 1436 | G12: 498 | H12: 938 | I12: 351.75
B13: 46082 | C13: 69037 | D13: GAYLE 18WP | E13: 30X100 G | F13: 196 | G13: 0 | H13: 146 | I13: 438
B14: 46082 | C14: 69037 | D14: GAYLE 18WP | E14: 30X100 G | F14: 0 | G14: 240 | H14: 70 | I14: 210
B15: 46082 | C15: 84793 | D15: VESTORIA 20WG | E15: 25X15 G | F15: 2 | G15: 0 | H15: 2 | I15: 0.75
B16: 46082 | C16: 84793 | D16: VESTORIA 20WG | E16: 25X15 G | F16: 746 | G16: 283 | H16: 776 | I16: 291
B17: 46082 | C17: 84793 | D17: VESTORIA 20WG | E17: 25X15 G | F17: 925 | G17: 42 | H17: 891 | I17: 334.125
B18: 46082 | C18: 84793 | D18: VESTORIA 20WG | E18: 25X15 G | F18: 1408 | G18: 6 | H18: 1048 | I18: 393
... B55: 46224 | C55: 53508 | D55: REVUS 250 SC | E55: 20X100 ML | F55: 84 | G55: 23 | H55: 82 | I55: 164
B56: 46224 | C56: 53924 | D56: REVUS 250 SC | E56: 10x500 ML | F56: 10 | G56: 0 | H56: 10 | I56: 50
B57: 46224 | C57: 53924 | D57: REVUS 250 SC | E57: 10x500 ML | F57: 34 | G57: 1 | H57: 33 | I57: 165
B58: 46224 | C58: 53924 | D58: REVUS 250 SC | E58: 10x500 ML | F58: 36 | G58: 9 | H58: 27 | I58: 135
B59: 46224 | C59: 67637 | D59: RIFIT PLUS 37 | E59: 20X250 ML | F59: 181 | G59: 2 | H59: 244 | I59: 1220
B60: 46224 | C60: 67637 | D60: RIFIT PLUS 37 | E60: 20X250 ML | F60: 322 | G60: 266 | H60: 239 | I60: 1195
B61: 46224 | C61: 75062 | D61: CALARIS XTRA | E61: 20X500 ML | F61: 1019 | G61: 0 | H61: 78 | I61: 780
B62: 46224 | C62: 75062 | D62: CALARIS XTRA | E62: 20X500 ML | F62: 0 | G62: 462 | H62: 730 | I62: 7300
B63: 46235 | C63: 46420 | D63: FILIA | E63: 20X100 ML | F63: 61 | G63: -8 | H63: 69 | I63: 138
B64: 46235 | C64: 67637 | D64: RIFIT PLUS 37 | E64: 20X250 ML | F64: 523 | G64: 200 | H64: 323 | I64: 1615
B65: 46235 | C65: 78917 | D65: RIFIT PLUS 37 | E65: 20x165 ML | F65: 11 | G65: 8 | H65: 3 | I65: 9.9
B66: 46235 | C66: 85803 | D66: CARIAL FLEX | E66: 3x10x70 G | F66: 434 | G66: 314 | H66: 120 | I66: 252
B67: 46255 | C67: 67637 | D67: RIFIT PLUS 37 | E67: 20X250 ML | F67: 309 | G67: 6 | H67: 308 | I67: 1540
B68: 46255 | C68: 67637 | D68: RIFIT PLUS 37 | E68: 20X250 ML | F68: 0 | G68: 266 | H68: 197 | I68: 985
B69: 46255 | C69: 85803 | D69: CARIAL FLEX | E69: 3x10x70 G | F69: 65 | G69: 0 | H69: 65 | I69: 136.5
B70: 46255 | C70: 85803 | D70: CARIAL FLEX | E70: 3x10x70 G | F70: 188 | G70: 12 | H70: 176 | I70: 369.6
B71: 46255 | C71: 85803 | D71: CARIAL FLEX | E71: 3x10x70 G | F71: 237 | G71: 1 | H71: 230 | I71: 483
B72: 46266 | C72: 34001 | D72: SCORE 250 EC | E72: 10X500 ML | F72: 0 | G72: -32 | H72: 32 | I72: 160
B73: 46266 | C73: 43978 | D73: VOLIAM FLEXI 300 SC | E73: 20X50 ML | F73: 0 | G73: -163 | H73: 163 | I73: 163
B74: 46266 | C74: 55458 | D74: FILIA | E74: 20X50 ML | F74: 485 | G74: -131 | H74: 616 | I74: 616
B75: 46266 | C75: 57918 | D75: FILIA | E75: 10x500 ML | F75: 265 | G75: 55 | H75: 210 | I75: 1050
B76: 46286 | C76: 30593 | D76: SCORE 250 EC | E76: 20X100 ML | F76: 266 | G76: 321 | H76: 0 | I76: 0
B77: 46286 | C77: 34001 | D77: SCORE 250 EC | E77: 10X500 ML | F77: 23 | G77: 1 | H77: 22 | I77: 110
B78: 46286 | C78: 55458 | D78: FILIA | E78: 20X50 ML | F78: 421 | G78: 54 | H78: 387 | I78: 387
B79: 46286 | C79: 55458 | D79: FILIA | E79: 20X50ml | F79: 229 | G79: 60 | H79: 178 | I79: 178
...

Sheet CP-June
E3: Values
A4: EXPIRY ON (MONTH) | B4: AGI Code | C4: Name of Products | D4: Pack Size | E4: Sum of EXPIRY QTY CM | F4: Sum of Kg /Ltr
A5: 46229 | B5: 53924 | C5: REVUS 250 SC | D5: 10X500 ML | E5: 55 | F5: 275
A6: 46260 | B6: 85803 | C6: CARIAL FLEX | D6: 3x10x70 G | E6: 721 | F6: 1514.1
A7: 46414 | B7: 53508 | C7: REVUS 250 SC | D7: 20X100 ML | E7: 198 | F7: 396
A8: 46471 | B8: 55458 | C8: FILIA 525 SE | D8: 20 x 50 ML | E8: 842 | F8: 842
A9: 46473 | B9: 58513 | C9: REVUS 250 SC | D9: 20 x 50 ML | E9: 960 | F9: 960
A10: 46473 | B10: 70897 | C10: PROCLAIM 05 SG | D10: 2X10X30 GM | E10: 1694 | F10: 1016.4
A11: 46473 | B11: 87199 | C11: PROCLAIM 05 SG | D11: 4X 12 X 10 GM | E11: 2571 | F11: 1234.08
A12: 46473 | B12: 87224 | C12: DENIM FIT 50 WG | D12: 4x12x10 G | E12: 326 | F12: 156.48
A13: 46504 | B13: 16238 | C13: THIOVIT 80WG | D13: 10 X 500 GM | E13: 332 | F13: 1660
A14: 46504 | B14: 61124 | C14: PEGASUS | D14: 20 X 100 ML | E14: 238 | F14: 476
A15: 46504 | B15: 85250 | C15: ARMURE 30EC | D15: 20 X 100 ML | E15: 699 | F15: 1398
A16: 46534 | B16: 38775 | C16: RIDOMIL GOLD MZ 68 WG | D16: 30 X 100 GM | E16: 1847 | F16: 5541
... A26: 46565 | B26: 92798 | C26: THIOVIT 80WG | D26: 12 X 1 KG | E26: 1337 | F26: 16044
A27: Grand Total | E27: 52228 | F27: 87400.66

Sheet CP data
A2: ITEM NO | B2: Name Of WH | C2: MONTH | D2: AGI Code | E2: Name of Products | F2: Pack Size | G2: EXPIRY QTY LM | H2: EXPIRY QTY CM | I2: EXPIRY BATCH CM | J2: EXPIRY ON (MONTH) | K2: SOLD QTY | L2: Total Qty | M2: OLD MRP | N2: NEW MRP | O2: REMARKS | P2: Kg /Ltr | Q2: Conv.R
A3: 1 | B3: DHAKA | C3: June | D3: 85803 | E3: CARIAL FLEX | F3: 3x10x70 G | G3: 174 | H3: 174 | I3: SCH4I2526 | J3: 46260 | K3: 0 | L3: 174 | P3: =H3*Q3 -> 365.4 | Q3: =IFERROR(VLOOKUP(D3,'Cp Conv.'!$A$2:$D$112,4,0),"0") -> 2.1
A4: 2 | B4: DHAKA | C4: June | D4: 87224 | E4: DENIM FIT 50 WG | F4: 4x12x10 G | G4: 181 | H4: 55 | I4: SCH5D2003 | J4: 46473 | K4: 81 | L4: 55 | P4: =H4*Q4 -> 26.4 | Q4: =IFERROR(VLOOKUP(D4,'Cp Conv.'!$A$2:$D$112,4,0),"0") -> 0.48
A5: 3 | B5: DHAKA | C5: June | D5: 87221 | E5: ACTARA 25WG | F5: 20X12 X 5 GM | G5: 224 | H5: 407 | I5: SCH5FW2011 | J5: 46534 | K5: 111 | L5: 407 | P5: =H5*Q5 -> 488.4 | Q5: =IFERROR(VLOOKUP(D5,'Cp Conv.'!$A$2:$D$112,4,0),"0") -> 1.2
A6: 4 | B6: DHAKA | C6: June | D6: 85250 | E6: ARMURE 30EC | F6: 20 X 100 ML | G6: 153 | H6: 147 | I6: SCH5E093 | J6: 46504 | K6: 1 | L6: 147 | P6: =H6*Q6 -> 294 | Q6: =IFERROR(VLOOKUP(D6,'Cp Conv.'!$A$2:$D$112,4,0),"0") -> 2
A7: 5 | B7: DHAKA | C7: June | D7: 43868 | E7: LASER 10 WP | F7: 4 X 30 X 25 GM | G7: 645 | H7: 715 | I7: RB20250603 | J7: 46534 | K7: 385 | L7: 672 | P7: =H7*Q7 -> 2145 | Q7: =IFERROR(VLOOKUP(D7,'Cp Conv.'!$A$2:$D$112,4,0),"0") -> 3
A8: 6 | B8: DHAKA | C8: June | D8: 80927 | E8: MIRAVIS DUO 20SC | F8: 20 x 50 ML | G8: 3862 | H8: 3769 | I8: SCH5F00084 | J8: 46534 | K8: 4 | L8: 4269 | P8: =H8*Q8 -> 3769 | Q8: =IFERROR(VLOOKUP(D8,'Cp Conv.'!$A$2:$D$112,4,0),"0") -> 1
A9: 7 | B9: DHAKA | C9: June | D9: 80927 | E9: MIRAVIS DUO 20SC | F9: 20 x 50 ML | G9: 0 | H9: 500 | I9: SCH5G00116 | J9: 46565 | P9: =H9*Q9 -> 500 | Q9: =IFERROR(VLOOKUP(D9,'Cp Conv.'!$A$2:$D$112,4,0),"0") -> 1
A10: 8 | B10: DHAKA | C10: June | D10: 81359 | E10: MIRAVIS DUO 20SC | F10: 20 X 100 ML | G10: 0 | H10: 178 | I10: SCH5G00116 | J10: 46565 | K10: 0 | L10: 178 | P10: =H10*Q10 -> 356 | Q10: =IFERROR(VLOOKUP(D10,'Cp Conv.'!$A$2:$D$112,4,0),"0") -> 2
A11: 9 | B11: DHAKA | C11: June | D11: 61124 | E11: PEGASUS | F11: 20 X 100 ML | G11: 346 | H11: 215 | I11: SCH5ES01012 | J11: 46504 | K11: 39 | L11: 214 | P11: =H11*Q11 -> 430 | Q11: =IFERROR(VLOOKUP(D11,'Cp Conv.'!$A$2:$D$112,4,0),"0") -> 2
A12: 10 | B12: DHAKA | C12: June | D12: 43978 | E12: VOLIAM FLEXI 300 SC | F12: 20 X 50 ML | G12: 0 | H12: 526 | I12: SCH5GS2056 | J12: 46565 | K12: 241 | L12: 2209 | O12: Dec-27(1738) carton | P12: =H12*Q12 -> 526 | Q12: =IFERROR(VLOOKUP(D12,'Cp Conv.'!$A$2:$D$112,4,0),"0") -> 1
A13: 11 | B13: DHAKA | C13: June | D13: 87199 | E13: PROCLAIM 05 SG | F13: 4X 12 X 10 GM | G13: 233 | H13: 547 | I13: SCH5DW3005 | J13: 46473 | K13: 101 | L13: 544 | P13: =H13*Q13 -> 262.56 | Q13: =IFERROR(VLOOKUP(D13,'Cp Conv.'!$A$2:$D$112,4,0),"0") -> 0.48
A14: 12 | B14: DHAKA | C14: June | D14: 70897 | E14: PROCLAIM 05 SG | F14: 2X10X30 GM | G14: 0 | H14: 226 | I14: SCH5DW3005 | J14: 46473 | K14: 2 | L14: 883 | O14: March-28(667)carton. | P14: =H14*Q14 -> 135.6 | Q14: =IFERROR(VLOOKUP(D14,'Cp Conv.'!$A$2:$D$112,4,0),"0") -> 0.6
A15: 13 | B15: DHAKA | C15: June | D15: 53924 | E15: REVUS 250 SC | F15: 10X500 ML | G15: 21 | H15: 21 | I15: SCH4H2E015 | J15: 46229 | K15: 0 | L15: 21 | P15: =H15*Q15 -> 105 | Q15: =IFERROR(VLOOKUP(D15,'Cp Conv.'!$A$2:$D$112,4,0),"0") -> 5
A16: 14 | B16: DHAKA | C16: June | D16: 53508 | E16: REVUS 250 SC | F16: 20X100 ML | G16: 399 | H16: 192 | I16: SCH5B2E004 | J16: 46414 | K16: 0 | L16: 190 | P16: =H16*Q16 -> 384 | Q16: =IFERROR(VLOOKUP(D16,'Cp Conv.'!$A$2:$D$112,4,0),"0") -> 2
A17: 15 | B17: DHAKA | C17: June | D17: 58513 | E17: REVUS 250 SC | F17: 20 X 50 ML | G17: 935 | H17: 389 | I17: SCH5D2E007 | J17: 46473 | K17: 5 | L17: 385 | P17: =H17*Q17 -> 389 | Q17: =IFERROR(VLOOKUP(D17,'Cp Conv.'!$A$2:$D$112,4,0),"0") -> 1
A18: 16 | B18: DHAKA | C18: June | D18: 38776 | E18: RIDOMIL GOLD MZ 68 WG | F18: 10X 500 GM | G18: 565 | H18: 154 | I18: SCH5F135RM | J18: 46534 | K18: 175 | L18: 154 | P18: =H18*Q18 -> 770 | Q18: =IFERROR(VLOOKUP(D18,'Cp Conv.'!$A$2:$D$112,4,0),"0") -> 5
A19: 17 | B19: DHAKA | C19: June | D19: 38775 | E19: RIDOMIL GOLD MZ 68 WG | F19: 30 X 100 GM | G19: 1762 | H19: 697 | I19: SCH5F134RM | J19: 46534 | K19: 328 | L19: 670 | P19: =H19*Q19 -> 2091 | Q19: =IFERROR(VLOOKUP(D19,'Cp Conv.'!$A$2:$D$112,4,0),"0") -> 3
A20: 18 | B20: DHAKA | C20: June | D20: 92798 | E20: THIOVIT 80WG | F20: 12 X 1 KG | H20: 467 | I20: SCH5G22918 | J20: 46565 | L20: 163 | O20: Oct-27(1150). | P20: =H20*Q20 -> 5604 | Q20: =IFERROR(VLOOKUP(D20,'Cp Conv.'!$A$2:$D$112,4,0),"0") -> 12
A21: 19 | B21: DHAKA | C21: June | D21: 16238 | E21: THIOVIT 80WG | F21: 10 X 500 GM | G21: 408 | H21: 271 | I21: SCH5E22110 | J21: 46504 | K21: 0 | L21: 246 | P21: =H21*Q21 -> 1355 | Q21: =IFERROR(VLOOKUP(D21,'Cp Conv.'!$A$2:$D$112,4,0),"0") -> 5
A22: 20 | B22: DHAKA | C22: June | D22: 52537 | E22: JAZZ | F22: 10X500 GM | G22: 0 | H22: 368 | I22: DKC-1287 | J22: 46565 | K22: 0 | L22: 246 | P22: =H22*Q22 -> 1840 | Q22: =IFERROR(VLOOKUP(D22,'Cp Conv.'!$A$2:$D$112,4,0),"0") -> 5
A23: 21 | B23: CTG WH | C23: June | D23: 85250 | E23: ARMURE 30EC | F23: 20 X 100 ML | G23: 162 | H23: 162 | I23: SCH5E2093 | J23: 46504 | K23: 0 | L23: 162 | P23: =H23*Q23 -> 324 | Q23: =IFERROR(VLOOKUP(D23,'Cp Conv.'!$A$2:$D$112,4,0),"0") -> 2
A24: 22 | B24: CTG WH | C24: June | D24: 87221 | E24: ACTARA 25WG | F24: 20X12 X 5 GM | G24: 238 | H24: 935 | I24: SCH5FW2011 | J24: 46534 | K24: 29 | L24: 751 | P24: =H24*Q24 -> 1122 | Q24: =IFERROR(VLOOKUP(D24,'Cp Conv.'!$A$2:$D$112,4,0),"0") -> 1.2
A25: 23 | B25: CTG WH | C25: June | D25: 87224 | E25: DENIM FIT 50 WG | F25: 4x12x10 G | G25: 238 | H25: 65 | I25: SCH5D2003 | J25: 46473 | K25: 4 | L25: 65 | P25: =H25*Q25 -> 31.2 | Q25: =IFERROR(VLOOKUP(D25,'Cp Conv.'!$A$2:$D$112,4,0),"0") -> 0.48
A26: 24 | B26: CTG WH | C26: June | D26: 55458 | E26: FILIA 525 SE | F26: 20 X 50 ML | G26: 18 | H26: 18 | I26: SCH5DS2002 | J26: 46471 | K26: 0 | L26: 869 | P26: =H26*Q26 -> 18 | Q26: =IFERROR(VLOOKUP(D26,'Cp Conv.'!$A$2:$D$112,4,0),"0") -> 1
A27: 25 | B27: CTG WH | C27: June | D27: 43868 | E27: LASER 10 WP | F27: 4 X 30 X 25 GM | G27: 1879 | H27: 1325 | I27: RB20250601 | J27: 46534 | K27: 34 | L27: 1325 | P27: =H27*Q27 -> 3975 | Q27: =IFERROR(VLOOKUP(D27,'Cp Conv.'!$A$2:$D$112,4,0),"0") -> 3
A28: 26 | B28: CTG WH | C28: June | D28: 80927 | E28: MIRAVIS DUO 20SC | F28: 20 x 50 ML | G28: 6428 | H28: 6427 | I28: SCH5F00076 | J28: 46534 | K28: 1 | L28: 6427 | P28: =H28*Q28 -> 6427 | Q28: =IFERROR(VLOOKUP(D28,'Cp Conv.'!$A$2:$D$112,4,0),"0") -> 1
A29: 27 | B29: CTG WH | C29: June | D29: 81359 | E29: MIRAVIS DUO 20SC | F29: 20 X 100 ML | G29: 0 | H29: 442 | I29: SCH5G00116 | J29: 46565 | K29: 0 | L29: 442 | P29: =H29*Q29 -> 884 | Q29: =IFERROR(VLOOKUP(D29,'Cp Conv.'!$A$2:$D$112,4,0),"0") -> 2
A30: 28 | B30: CTG WH | C30: June | D30: 61124 | E30: PEGASUS | F30: 20 X 100 ML | G30: 410 | H30: 15 | I30: SCH5ES1008 | J30: 46504 | K30: 100 | L30: 15 | P30: =H30*Q30 -> 30 | Q30: =IFERROR(VLOOKUP(D30,'Cp Conv.'!$A$2:$D$112,4,0),"0") -> 2
A31: 29 | B31: PLANT | C31: June | D31: 87199 | E31: PROCLAIM 05 SG | F31: 4X 12 X 10 GM | G31: 0 | H31: 165 | I31: SCH5DW3005 | J31: 46473 | L31: 672 | P31: =H31*Q31 -> 79.2 | Q31: =IFERROR(VLOOKUP(D31,'Cp Conv.'!$A$2:$D$112,4,0),"0") -> 0.48
A32: 30 | B32: CTG WH | C32: June | D32: 87199 | E32: PROCLAIM 05 SG | F32: 4X 12 X 10 GM | G32: 228 | H32: 691 | I32: SCH5D003004 | J32: 46473 | K32: 9 | L32: 691 | P32: =H32*Q32 -> 331.68 | Q32: =IFERROR(VLOOKUP(D32,'Cp Conv.'!$A$2:$D$112,4,0),"0") -> 0.48
A33: 31 | B33: CTG WH | C33: June | D33: 70897 | E33: PROCLAIM 05 SG | F33: 2X10X30 GM | G33: 0 | H33: 550 | I33: SCH5D003005 | J33: 46473 | L33: 550 | P33: =H33*Q33 -> 330 | Q33: =IFERROR(VLOOKUP(D33,'Cp Conv.'!$A$2:$D$112,4,0),"0") -> 0.6
A34: 32 | B34: CTG WH | C34: June | D34: 58513 | E34: REVUS 250 SC | F34: 20 X 50 ML | G34: 434 | H34: 230 | I34: SCH5D2E007 | J34: 46473 | K34: 72 | L34: 230 | P34: =H34*Q34 -> 230 | Q34: =IFERROR(VLOOKUP(D34,'Cp Conv.'!$A$2:$D$112,4,0),"0") -> 1
A35: 33 | B35: CTG WH | C35: June | D35: 38775 | E35: RIDOMIL GOLD MZ 68 WG | F35: 30 X 100 GM | G35: 772 | H35: 405 | I35: SCH5F135RM | J35: 46534 | K35: 188 | L35: 405 | P35: =H35*Q35 -> 1215 | Q35: =IFERROR(VLOOKUP(D35,'Cp Conv.'!$A$2:$D$112,4,0),"0") -> 3
A36: 34 | B36: CTG WH | C36: June | D36: 38776 | E36: RIDOMIL GOLD MZ 68 WG | F36: 10X 500 GM | G36: 683 | H36: 73 | I36: SCH5F135RM | J36: 46534 | K36: 2 | L36: 73 | P36: =H36*Q36 -> 365 | Q36: =IFERROR(VLOOKUP(D36,'Cp Conv.'!$A$2:$D$112,4,0),"0") -> 5
A37: 35 | B37: CTG WH | C37: June | D37: 92798 | E37: THIOVIT 80WG | F37: 12 X 1 KG | G37: 0 | H37: 182 | I37: SCH5G22916 | J37: 46565 | L37: 12 | P37: =H37*Q37 -> 2184 | Q37: =IFERROR(VLOOKUP(D37,'Cp Conv.'!$A$2:$D$112,4,0),"0") -> 12
A38: 36 | B38: CTG WH | C38: June | D38: 43978 | E38: VOLIAM FLEXI 300 SC | F38: 20 X 50 ML | G38: 0 | H38: 465 | I38: SCH5G22064 | J38: 46565 | L38: 1772 | P38: =H38*Q38 -> 465 | Q38: =IFERROR(VLOOKUP(D38,'Cp Conv.'!$A$2:$D$112,4,0),"0") -> 1
A39: 37 | B39: BOGURA | C39: June | D39: 53924 | E39: REVUS 250 SC | F39: 10X500 ML | G39: 26 | H39: 20 | I39: SCH4H2E015 | J39: 46229 | K39: -112 | L39: 20 | P39: =H39*Q39 -> 100 | Q39: =IFERROR(VLOOKUP(D39,'Cp Conv.'!$A$2:$D$112,4,0),"0") -> 5
A40: 38 | B40: BOGURA | C40: June | D40: 85803 | E40: CARIAL FLEX | F40: 3x10x70 G | G40: 351 | H40: 351 | I40: SCH4I2526 | J40: 46260 | K40: 176 | L40: 351 | O40: Sales Return,50 CTN from DHK WH | P40: =H40*Q40 -> 737.1 | Q40: =IFERROR(VLOOKUP(D40,'Cp Conv.'!$A$2:$D$112,4,0),"0") -> 2.1
A41: 39 | B41: BOGURA | C41: June | D41: 53508 | E41: REVUS 250 SC | F41: 20X100 ML | G41: 420 | H41: 6 | I41: SCH5B2E003 | J41: 46414 | K41: 54 | L41: 4 | P41: =H41*Q41 -> 12 | Q41: =IFERROR(VLOOKUP(D41,'Cp Conv.'!$A$2:$D$112,4,0),"0") -> 2
...

Sheet Sheet10
C2: Name of Products | D2: Pack Size | E2: Total | F2: Expiry
C3: NK 7884 | D3: 20X1kg | E3: 40 | F3: 45287
C4: Honey Queen | D4: 10x100 gm | E4: 152 | F4: 45377
C5: Tishan | D5: 10x100 gm | E5: 0 | F5: 45468
C6: Dragon | D6: 10x100 gm | E6: 9 | F6: 45469
C7: CX 18 | D7: 10 X1Kg | E7: 1740 | F7: 45562
C8: Green ball | D8: 10x10gm | E8: 31.1 | F8: 45622
C9: Rigel | D9: 10x10gm | E9: 7 | F9: 45623
C10: Rigel | D10: 10X5gm | E10: 4.95 | F10: 45654
C11: WIN 207 | D11: 30 x 1 kg | E11: 0 | F11: 45772
C12: Syngenta Hybrid Dhan-8 | D12: 30X1kg | E12: 11430 | F12: 45774
C13: Sugar Queen | D13: 10x10gm | E13: 9.7 | F13: 45777
C14: Honey Queen | D14: 10x100 gm | E14: 0 | F14: 45804
... C92: Bipul Plus | D92: 10X5gm | E92: 0 | F92: 46412

Sheet SEED- June
E3: Values
A4: EXPIRY ON (MONTH) | B4: AGI Code | C4: Name of Products | D4: Pack size | E4: Sum of EXPIRY QTY CM | F4: Sum of Kg-ltr
A5: 45271 | B5: 4137319 | C5: NK 7884 | D5: 20X1kg | E5: 2 | F5: 40
A6: 45355 | B6: 4101765 | C6: Honey Queen | D6: 10x100 gm | E6: 150 | F6: 150
A7: 45546 | B7: 4144176 | C7: CX 18 | D7: 10 X1Kg | E7: 174 | F7: 1740
A8: 45716 | B8: 4181094 | C8: NK 6514 | D8: 30X1 kg | E8: 202 | F8: 6060
A9: 45750 | B9: 4160722 | C9: WIN 207 | D9: 30 x 1 kg | E9: 172 | F9: 5160
A10: 45750 | B10: 4165682 | C10: Syn Hyb Dhan-8 BD | D10: 30X1kg | E10: 172 | F10: 5160
A11: 45839 | B11: 4118665 | C11: Sugar Queen | D11: 10X10 GM | E11: 50 | F11: 5
A12: 45966 | B12: 254871 | C12: Gourab | D12: 10 x 10 gm | E12: 143 | F12: 14.3
A13: 45966 | B13: 4165670 | C13: Syn Hyb Dhan-8 IND | D13: 30X1kg | E13: 211 | F13: 6330
A14: 46089 | B14: 351343 | C14: Dragon | D14: 10x100 gm | E14: 938 | F14: 938
A15: 46089 | B15: 4132141 | C15: Dragon Super | D15: 10X100gm | E15: 234 | F15: 234
A16: 46089 | B16: 4165680 | C16: Syngenta S -1203 BD | D16: 30X1kg | E16: 722 | F16: 21660
... A72: 46513 | B72: 351343 | C72: Dragon | D72: 10x100 gm | E72: 40 | F72: 40
A73: Grand Total | E73: 37203.1 | F73: 973375.7

Sheet SE DATA
A2: ITEM NO | B2: Name Of WH | C2: MONTH | D2: AGI Code | E2: Name of Products | F2: Pack size | G2: EXPIRY QTY LM | H2: EXPIRY QTY CM | I2: EXPIRY BATCH CM | J2: EXPIRY ON (MONTH) | K2: SOLD QTY | L2: Total Qty | M2: OLD MRP | N2: NEW MRP | O2: REMARKS | P2: Kg-ltr | Q2: Conv.R
A3: 1 | B3: CTG WH | C3: June | D3: 4011999 | E3: DAISY | F3: 10X10 GM | G3: 37 | H3: 18 | I3: SBV26A677 | J3: 46502 | K3: =IFERROR(VLOOKUP(D3,'[2]Sales(CP & Seeds)'!$A$2:$C$186,3,0),"0") -> 20 | L3: =IFERROR(VLOOKUP(D3,'[2]Seeds Stock'!$A$2:$G$133,3,0),"0") -> 53 | P3: =H3*Q3 -> 1.8 | Q3: =IFERROR(VLOOKUP(D3,'Seed conv.'!$A$2:$D$188,4,0),"0") -> 0.1
A4: 2 | B4: CTG WH | C4: June | D4: 4217472 | E4: Sujon | F4: 10 X 10gm | G4: 7 | H4: 7 | I4: SBV26A674 | J4: 46502 | K4: =IFERROR(VLOOKUP(D4,'[2]Sales(CP & Seeds)'!$A$2:$C$186,3,0),"0") -> 0 | L4: =IFERROR(VLOOKUP(D4,'[2]Seeds Stock'!$A$2:$G$133,3,0),"0") -> 45 | P4: =H4*Q4 -> 0.7 | Q4: =IFERROR(VLOOKUP(D4,'Seed conv.'!$A$2:$D$188,4,0),"0") -> 0.1
A5: 3 | B5: CTG WH | C5: June | D5: 4217472 | E5: Sujon | F5: 10 X 10gm | G5: 16 | H5: 16 | I5: SBV26A647 | J5: 46532 | K5: =IFERROR(VLOOKUP(D5,'[2]Sales(CP & Seeds)'!$A$2:$C$186,3,0),"0") -> 0 | L5: =IFERROR(VLOOKUP(D5,'[2]Seeds Stock'!$A$2:$G$133,3,0),"0") -> 45 | P5: =H5*Q5 -> 1.6 | Q5: =IFERROR(VLOOKUP(D5,'Seed conv.'!$A$2:$D$188,4,0),"0") -> 0.1
A6: 4 | B6: CTG WH | C6: June | D6: 4227101 | E6: Sujon | F6: 10 X 5gm | G6: 33 | H6: 33 | I6: SBV26A647 | J6: 46532 | K6: =IFERROR(VLOOKUP(D6,'[2]Sales(CP & Seeds)'!$A$2:$C$186,3,0),"0") -> 0 | L6: =IFERROR(VLOOKUP(D6,'[2]Seeds Stock'!$A$2:$G$133,3,0),"0") -> 63 | P6: =H6*Q6 -> 1.65 | Q6: =IFERROR(VLOOKUP(D6,'Seed conv.'!$A$2:$D$188,4,0),"0") -> 0.05
A7: 5 | B7: BOGRA | C7: June | D7: 4137319 | E7: NK 7884 | F7: 20X1kg | G7: 2 | H7: 2 | I7: 17727595 | J7: 45271 | K7: 0 | L7: 2 | O7: Reworked | P7: =H7*Q7 -> 40 | Q7: =IFERROR(VLOOKUP(D7,'Seed conv.'!$A$2:$D$188,4,0),"0") -> 20
A8: 6 | B8: BOGRA | C8: June | D8: 4101765 | E8: Honey Queen | F8: 10x100 gm | G8: 152 | H8: 150 | I8: SBV22J092 | J8: 45355 | K8: 0 | L8: 145.5 | O8: Expired | P8: =H8*Q8 -> 150 | Q8: =IFERROR(VLOOKUP(D8,'Seed conv.'!$A$2:$D$188,4,0),"0") -> 1
A9: 7 | B9: BOGRA | C9: June | D9: 4144176 | E9: CX 18 | F9: 10 X1Kg | G9: 174 | H9: 174 | I9: 6E12217051 | J9: 45546 | K9: 0 | L9: 174 | O9: Bulk | P9: =H9*Q9 -> 1740 | Q9: =IFERROR(VLOOKUP(D9,'Seed conv.'!$A$2:$D$188,4,0),"0") -> 10
A10: 8 | B10: BOGRA | C10: June | D10: 4170977 | E10: Little Star | F10: 10X10 gm | G10: 305 | H10: 305 | I10: SBV24I371 | J10: 45700 | K10: 62 | L10: 205 | P10: =H10*Q10 -> 30.5 | Q10: =IFERROR(VLOOKUP(D10,'Seed conv.'!$A$2:$D$188,4,0),"0") -> 0.1
A11: 9 | B11: BOGRA | C11: June | D11: 4181094 | E11: NK 6514 | F11: 30X1 kg | G11: 202 | H11: 202 | I11: 18815390 | J11: 45716 | K11: 0 | L11: 780 | O11: Expired | P11: =H11*Q11 -> 6060 | Q11: =IFERROR(VLOOKUP(D11,'Seed conv.'!$A$2:$D$188,4,0),"0") -> 30
A12: 10 | B12: BOGRA | C12: June | D12: 4165682 | E12: Syn Hyb Dhan-8 BD | F12: 30X1kg | G12: 172 | H12: 172 | I12: 18812952 | J12: 45750 | K12: 0 | L12: 263 | O12: Expired (Write Off Proposed) | P12: =H12*Q12 -> 5160 | Q12: =IFERROR(VLOOKUP(D12,'Seed conv.'!$A$2:$D$188,4,0),"0") -> 30
A13: 11 | B13: BOGRA | C13: June | D13: 4160722 | E13: WIN 207 | F13: 30 x 1 kg | G13: 172 | H13: 172 | I13: 140605071 | J13: 45750 | K13: 0 | L13: 172 | O13: Reworked | P13: =H13*Q13 -> 5160 | Q13: =IFERROR(VLOOKUP(D13,'Seed conv.'!$A$2:$D$188,4,0),"0") -> 30
A14: 12 | B14: BOGRA | C14: June | D14: 4118665 | E14: Sugar Queen | F14: 10X10 gm | G14: 50 | H14: 50 | I14: SBV24D166 | J14: 45839 | K14: 0 | L14: 209 | P14: =H14*Q14 -> 5 | Q14: =IFERROR(VLOOKUP(D14,'Seed conv.'!$A$2:$D$188,4,0),"0") -> 0.1
A15: 13 | B15: BOGRA | C15: June | D15: 4118665 | E15: Sugar Queen | F15: 10X10 gm | G15: 97 | H15: 87 | I15: SBV24E257 | J15: 45964 | K15: 0 | L15: 209 | O15: Expired (Write Off Proposed) | P15: =H15*Q15 -> 8.7 | Q15: =IFERROR(VLOOKUP(D15,'Seed conv.'!$A$2:$D$188,4,0),"0") -> 0.1
A16: 14 | B16: BOGRA | C16: June | D16: 254871 | E16: Gourab | F16: 10 x 10 gm | G16: 143 | H16: 143 | I16: SBV24G293 | J16: 45966 | K16: 0 | L16: 143 | P16: =H16*Q16 -> 14.3 | Q16: =IFERROR(VLOOKUP(D16,'Seed conv.'!$A$2:$D$188,4,0),"0") -> 0.1
A17: 15 | B17: BOGRA | C17: June | D17: 4165670 | E17: Syn Hyb Dhan-8 IND | F17: 30X1kg | G17: 211 | H17: 211 | I17: 19898682 | J17: 45966 | K17: 32 | L17: 1305.7 | P17: =H17*Q17 -> 6330 | Q17: =IFERROR(VLOOKUP(D17,'Seed conv.'!$A$2:$D$188,4,0),"0") -> 30
A18: 16 | B18: BOGRA | C18: June | D18: 4165682 | E18: Syn Hyb Dhan-8 BD | F18: 30X1kg | G18: 132 | H18: 132 | I18: 19710751 | J18: 45982 | K18: 0 | P18: =H18*Q18 -> 3960 | Q18: =IFERROR(VLOOKUP(D18,'Seed conv.'!$A$2:$D$188,4,0),"0") -> 30
A19: 17 | B19: BOGRA | C19: June | D19: 351343 | E19: Dragon | F19: 10x100 gm | G19: 938 | H19: 938 | I19: SBV22I385 | J19: 46089 | K19: 0 | L19: 977.9 | O19: REWORKED | P19: =H19*Q19 -> 938 | Q19: =IFERROR(VLOOKUP(D19,'Seed conv.'!$A$2:$D$188,4,0),"0") -> 1
A20: 18 | B20: BOGRA | C20: June | D20: 4132141 | E20: Dragon Super | F20: 10X100gm | G20: 234 | H20: 234 | I20: SBV24I379 | J20: 46089 | K20: 0 | L20: 473.6 | O20: REWORKED | P20: =H20*Q20 -> 234 | Q20: =IFERROR(VLOOKUP(D20,'Seed conv.'!$A$2:$D$188,4,0),"0") -> 1
A21: 19 | B21: BOGRA | C21: June | D21: 4165680 | E21: Syngenta S -1203 BD | F21: 30X1kg | G21: 722 | H21: 722 | I21: 140309121 | J21: 46089 | K21: 5 | L21: 4461 | O21: 722 BAG SALES RETURN | P21: =H21*Q21 -> 21660 | Q21: =IFERROR(VLOOKUP(D21,'Seed conv.'!$A$2:$D$188,4,0),"0") -> 30
A22: 20 | B22: BOGRA | C22: June | D22: 4165668 | E22: Syngenta S -1205 | F22: 30X1kg | G22: 69 | H22: 69 | I22: 150509231 | J22: 46145 | K22: 16 | L22: 6374 | O22: Reworked | P22: =H22*Q22 -> 2070 | Q22: =IFERROR(VLOOKUP(D22,'Seed conv.'!$A$2:$D$188,4,0),"0") -> 30
A23: 21 | B23: BOGRA | C23: June | D23: 4170972 | E23: Win-601 Import | F23: 30 x 1 kg | G23: 109 | H23: 109 | I23: 140111610 | J23: 46167 | K23: 0 | L23: 2231 | O23: Sales Return | P23: =H23*Q23 -> 3270 | Q23: =IFERROR(VLOOKUP(D23,'Seed conv.'!$A$2:$D$188,4,0),"0") -> 30
A24: 22 | B24: BOGRA | C24: June | D24: 4181094 | E24: NK 6514 | F24: 30X1 kg | G24: 59 | H24: 59 | I24: 18961830 | J24: 46179 | K24: 0 | L24: 780 | O24: Reworked 85 SAC | P24: =H24*Q24 -> 1770 | Q24: =IFERROR(VLOOKUP(D24,'Seed conv.'!$A$2:$D$188,4,0),"0") -> 30
A25: 23 | B25: BOGRA | C25: June | D25: 4226245 | E25: NK 7321 | F25: 30X1kg | G25: 1 | H25: 1 | I25: 20161168 | J25: 46208 | K25: 0 | L25: 1 | O25: Sales Return | P25: =H25*Q25 -> 30 | Q25: =IFERROR(VLOOKUP(D25,'Seed conv.'!$A$2:$D$188,4,0),"0") -> 30
A26: 24 | B26: BOGRA | C26: June | D26: 4118665 | E26: Sugar Queen | F26: 10X10 gm | G26: 60 | H26: 60 | I26: SBV25D471 | J26: 46289 | K26: 0 | L26: 209 | O26: Reworked | P26: =H26*Q26 -> 6 | Q26: =IFERROR(VLOOKUP(D26,'Seed conv.'!$A$2:$D$188,4,0),"0") -> 0.1
A27: 25 | B27: BOGRA | C27: June | D27: 4158231 | E27: Summer Green | F27: 10X5gm | G27: 402 | H27: 352 | I27: SBV25E485 | J27: 46309 | K27: 0 | L27: 352 | P27: =H27*Q27 -> 35.2 | Q27: =IFERROR(VLOOKUP(D27,'Seed conv.'!$A$2:$D$188,4,0),"0") -> 0.1
A28: 26 | B28: BOGRA | C28: June | D28: 4160722 | E28: WIN 207 | F28: 30 x 1 kg | G28: 21 | H28: 21 | I28: 150706505 | J28: 46337 | K28: 0 | L28: 21 | P28: =H28*Q28 -> 630 | Q28: =IFERROR(VLOOKUP(D28,'Seed conv.'!$A$2:$D$188,4,0),"0") -> 30
A29: 27 | B29: BOGRA | C29: June | D29: 4165670 | E29: Syn Hyb Dhan-8 IND | F29: 30X1kg | G29: 1126 | H29: 1095 | I29: 20860869 | J29: 46347 | K29: 32 | L29: 1305.7 | O29: Imported 1511 Sac | P29: =H29*Q29 -> 32850 | Q29: =IFERROR(VLOOKUP(D29,'Seed conv.'!$A$2:$D$188,4,0),"0") -> 30
A30: 28 | B30: BOGRA | C30: June | D30: 4187261 | E30: SunRise | F30: 30 x 1 kg | G30: 1287 | H30: 1287 | I30: 19564757 | J30: 46348 | K30: 0 | L30: 1287 | O30: Sales Return | P30: =H30*Q30 -> 38610 | Q30: =IFERROR(VLOOKUP(D30,'Seed conv.'!$A$2:$D$188,4,0),"0") -> 30
A31: 29 | B31: BOGRA | C31: June | D31: 4178643 | E31: NK 7804 | F31: 30 x 1 kg | G31: 1280 | H31: 1280 | I31: 20694629 | J31: 46366 | K31: 0 | L31: 1273 | O31: Reworked | P31: =H31*Q31 -> 38400 | Q31: =IFERROR(VLOOKUP(D31,'Seed conv.'!$A$2:$D$188,4,0),"0") -> 30
A32: 30 | B32: BOGRA | C32: June | D32: 4181098 | E32: Sunshine | F32: 15 x 2 kg | G32: 176 | H32: 176 | I32: 19564764 | J32: 46368 | K32: 0 | L32: 176 | O32: Sales Return | P32: =H32*Q32 -> 5280 | Q32: =IFERROR(VLOOKUP(D32,'Seed conv.'!$A$2:$D$188,4,0),"0") -> 30
A33: 31 | B33: BOGRA | C33: June | D33: 4165680 | E33: Syngenta S -1203 BD | F33: 30X1kg | G33: 4316 | H33: 4316 | I33: 140309114 | J33: 46368 | K33: 5 | L33: 4461 | O33: Sales Return | P33: =H33*Q33 -> 129480 | Q33: =IFERROR(VLOOKUP(D33,'Seed conv.'!$A$2:$D$188,4,0),"0") -> 30
A34: 32 | B34: BOGRA | C34: June | D34: 4135831 | E34: TO 3150 | F34: 10 x 10 gm | G34: 187 | H34: 187 | I34: SBV25F518 | J34: 46368 | K34: 0 | L34: 187 | O34: Production | P34: =H34*Q34 -> 18.7 | Q34: =IFERROR(VLOOKUP(D34,'Seed conv.'!$A$2:$D$188,4,0),"0") -> 0.1
A35: 33 | B35: BOGRA | C35: June | D35: 4135823 | E35: TO 3150 | F35: 10X5 gm | G35: 288 | H35: 288 | I35: SBV25G526 | J35: 46368 | K35: 0 | L35: 260 | O35: Production | P35: =H35*Q35 -> 14.4 | Q35: =IFERROR(VLOOKUP(D35,'Seed conv.'!$A$2:$D$188,4,0),"0") -> 0.05
A36: 34 | B36: BOGRA | C36: June | D36: 4114197 | E36: Green King (BG1137) | F36: 10X10gm | G36: 29 | H36: 29 | I36: SBV25I598 | J36: 46388 | K36: 0 | L36: 29 | O36: Production | P36: =H36*Q36 -> 2.9 | Q36: =IFERROR(VLOOKUP(D36,'Seed conv.'!$A$2:$D$188,4,0),"0") -> 0.1
A37: 35 | B37: BOGRA | C37: June | D37: 4181083 | E37: NH 7720 | F37: 30X1 kg | G37: 4715 | H37: 4715 | I37: 20763640 | J37: 46388 | K37: 0 | L37: 4558.66 | O37: Sales Return | P37: =H37*Q37 -> 141450 | Q37: =IFERROR(VLOOKUP(D37,'Seed conv.'!$A$2:$D$188,4,0),"0") -> 30
A38: 36 | B38: BOGRA | C38: June | D38: 4144723 | E38: Rigel | F38: 10X5 gm | G38: 433 | H38: 223 | I38: SBV25G558 | J38: 46388 | K38: 10 | L38: 333 | O38: Production | P38: =H38*Q38 -> 11.15 | Q38: =IFERROR(VLOOKUP(D38,'Seed conv.'!$A$2:$D$188,4,0),"0") -> 0.05
A39: 37 | B39: BOGRA | C39: June | D39: 254853 | E39: Green-60 | F39: 10 x 10 gm | G39: 1309 | H39: 374 | I39: SBV25G497 | J39: 46393 | K39: 282 | L39: 374 | O39: Reworked | P39: =H39*Q39 -> 37.4 | Q39: =IFERROR(VLOOKUP(D39,'Seed conv.'!$A$2:$D$188,4,0),"0") -> 0.1
A40: 38 | B40: BOGRA | C40: June | D40: 4135874 | E40: Testy | F40: 10 x 10 gm | G40: 59 | H40: 59 | I40: SBV25I594 | J40: 46393 | K40: 0 | L40: 59 | P40: =H40*Q40 -> 5.9 | Q40: =IFERROR(VLOOKUP(D40,'Seed conv.'!$A$2:$D$188,4,0),"0") -> 0.1
A41: 39 | B41: BOGRA | C41: June | D41: 4075565 | E41: TO 3038 | F41: 10 x 10 gm | G41: 110 | H41: 110 | I41: SBV25H566 | J41: 46393 | K41: 0 | L41: 110 | P41: =H41*Q41 -> 11 | Q41: =IFERROR(VLOOKUP(D41,'Seed conv.'!$A$2:$D$188,4,0),"0") -> 0.1
...

Sheet Bulk _ctg
A1: ITEM NO | B1: Name Of WH | C1: MONTH | D1: AGI Code | E1: Name of Products | F1: Pack Size | G1: EXPIRY QTY LM | H1: EXPIRY QTY CM (KG) | I1: EXPIRY BATCH CM | J1: EXPIRY ON (MONTH) | K1: Consumption QTY | L1: Total Stock | M1: OLD MRP | N1: NEW MRP | O1: Conv.R | P1: Remarks
A2: 1 | B2: PLANT | C2: June | D2: 169663 | E2: SOLVESSO 150 (APAC) | F2: 4x184 KG | G2: 2324 | H2: 1694 | I2: SV36502603 | J2: 46472 | K2: 630 | L2: 1694.3
A3: 2 | B3: PLANT | C3: June | D3: 38747 | E3: SOLVESSO 100 BULK KG PKA | F3: 4 x 179 KG | G3: 6352.1 | H3: 1211.4 | I3: SV38022519 | J3: 46414 | K3: 5140.7 | L3: 1211.4
A4: 3 | B4: CTG WH | C4: June | D4: 169663 | E4: SOLVESSO 150 (APAC) | F4: 4x184 KG | G4: 18400 | H4: 16928 | I4: SV36502603 | J4: 46472 | K4: 1472 | L4: 16928
A5: 4 | B5: CTG WH | C5: June | D5: 38747 | E5: SOLVESSO 100 BULK KG PKA | F5: 4 x 179 KG | G5: 24344 | H5: 20764 | I5: SV38022519 | J5: 46414 | K5: 3580 | L5: 20764
A6: 5 | B6: CTG WH | C6: June | D6: 85448 | E6: CARIAL FLEX 43 WG 600KG | F6: 1X600 KG | G6: 5400 | H6: 5400 | I6: SSP5A2500-001 | J6: 46414 | K6: 0 | L6: 5400
A7: 6 | B7: PLANT | C7: June | D7: 61488 | E7: 2,6-DI-TBUTYL-4-MRTHYL-PHENOL 1 KG BDA | F7: 30x25 KG | G7: 294.3 | H7: 823.4 | I7: 213175 | J7: 46472 | K7: -529.1 | L7: 823.449
A8: 8 | B8: CTG WH | C8: June | D8: 35452 | E8: GROZIN (Zinc Sulphate Mono) 25 KG BDA | F8: 40x25 kg | G8: 1341 | H8: 1341 | I8: ISKY20250227, 20250227 | J8: 46445 | K8: 0 | L8: 1392341
A9: 9 | B9: CTG WH | C9: June | D9: 72736 | E9: RIDOMIL GOLD MZ 68 WG 600 KG 124 | F9: 1X600 KG | G9: 0 | H9: 13800 | I9: IPT5F162-166 | J9: 46564 | K9: -13800 | L9: 97800
A10: 10 | B10: PLANT | C10: June | D10: 72736 | E10: RIDOMIL GOLD MZ 68 WG 600 KG 124 | F10: 1X600 KG | G10: 0 | H10: 5372 | I10: IPT5F162RM, IPT5F165RM | J10: 46534 | L10: 8690
A11: 11 | B11: CTG WH | C11: June | D11: 82461 | E11: ACTARA 25 WG 40 KG 22D | F11: 8X40 KG | G11: 0 | H11: 80 | I11: SIK5FW2012 | J11: 46564 | K11: -80 | L11: 80
A12: 12 | B12: PLANT | C12: June | D12: 60714 | E12: PEGASUS 50 SC 180L 22D | F12: 4X180 L | G12: 13.4 | H12: 13.4 | I12: SIK5ES1012 | J12: 46534 | K12: 0 | L12: 13.4
A13: 13 | B13: PLANT | C13: June | D13: 53649 | E13: REVUS 250 SC 200 L BDA | F13: 4X200 L | G13: 1418 | H13: 1418 | I13: SPL502E008,SPL502E009 | J13: 46503 | K13: 0 | L13: 1418
A14: 14 | B14: CTG WH | C14: June | D14: 53649 | E14: REVUS 250 SC 200 L BDA | F14: 4X200 L | G14: 1600 | H14: 1600 | I14: SPL502E009 | J14: 46503 | K14: 0 | L14: 1600
A15: Total | G15: =SUM(G2:G14) -> 61486.8 | H15: =SUM(H2:H14) -> 70445.2 | K15: =SUM(K2:K14) -> -3586.4 | L15: =SUM(L2:L14) -> 1548763.5 | O15: =IFERROR(VLOOKUP($E15,[2]CODE!#REF!,7,0),"0") -> 0
E21: Name of Products | F21: Pack Size | G21: EXPIRY QTY CM (KG) | H21: EXPIRY ON (MONTH)
E22: SOLVESSO 100 BULK KG PKA | F22: 4 x 179 KG | G22: 21975 | H22: 46414
E23: CARIAL FLEX 43 WG 600KG | F23: 1X600 KG | G23: 5400 | H23: 46414
E24: GROZIN (Zinc Sulphate Mono) 25 KG BDA | F24: 40x25 kg | G24: 1341 | H24: 46445
E25: SOLVESSO 150 (APAC) | F25: 4x184 KG | G25: 18622 | H25: 46473
E26: 2,6-DI-TBUTYL-4-MRTHYL-PHENOL 1 KG BDA | F26: 30x25 KG | G26: 823.4 | H26: 46473
E27: REVUS 250 SC 200 L BDA | F27: 4X200 L | G27: 3018 | H27: 46506
E28: PEGASUS 50 SC 180L 22D | F28: 4X180 L | G28: 13.4 | H28: 46533
E29: ACTARA 25 WG 40 KG 22D | F29: 8X40 KG | G29: 80 | H29: 46564
E30: RIDOMIL GOLD MZ 68 WG 600 KG 124 | F30: 1X600 KG | G30: 19172 | H30: 46564

Sheet Cp Conv.
A1: Due products and today's stock
A2: CODE | B2: PRODUCT | C2: PACK | D2: kg / Ltr
A3: 29568 | B3: SHOBICRON 425EC | C3: 20 X 50 ML | D3: 1
A4: 42123 | C4: 20 X 100 ML | D4: 2
A5: 29570 | C5: 10 X 500 ML | D5: 5
A6: 58888 | B6: TILT 250EC | C6: 20 X 50 ML | D6: 1
A7: 58889 | C7: 20 X 100 ML | D7: 2
A8: 58887 | C8: 10 X 500 ML | D8: 5
A9: 34002 | B9: SCORE 250EC | C9: 20 X 50 ML | D9: 1
A10: 30593 | C10: 20 X 100 ML | D10: 2
A11: 34001 | C11: 10 X 500 ML | D11: 5
A12: 35348 | B12: RIFIT 500 EC | C12: 20 X 100 ML | D12: 2
A13: 30688 | C13: 10 X 500 ML | D13: 5
A14: 59703 | B14: PROTOZIM | C14: 40 X 50 ML | D14: 2
A15: 59704 | C15: 20 X 100 ML | D15: 2
A16: 59769 | C16: 10 X 500 ML | D16: 5
A17: 58896 | B17: KARATE | C17: 50 X 50 ML | D17: 2.5
A18: 58890 | C18: 50 X 100 ML | D18: 5
A19: 58886 | C19: 10 X 500 ML | D19: 5
A20: 63105 | B20: VERTIMEC 018 EC | C20: 20 X 50 ML | D20: 1
A21: 63106 | C21: 20 X 100 ML | D21: 2
A22: 63107 | C22: 10 X 500 ML | D22: 5
A23: 43978 | B23: VOLIAM FLEXI 300 SC | C23: 20 X 50 ML | D23: 1
A24: 53294 | B24: AMISTAR TOP 325 SC | C24: 20 X 50 ML | D24: 1
A25: 88631 | C25: 20 X 50 ML | D25: 1
A26: 46652 | C26: 20 X 100 ML | D26: 2
A27: 88630 | C27: 20 X 100 ML | D27: 2
A28: 51574 | C28: 10 X 500 ML | D28: 5
A29: 88626 | C29: 10 X 500 ML | D29: 5
A30: 58513 | B30: REVUS 250 SC | C30: 20 X 50 ML | D30: 1
A31: 53508 | C31: 20 X 100 ML | D31: 2
A32: 53924 | C32: 10 X 500 ML | D32: 5
A33: 80926 | B33: INCIPIO | C33: 20 x 40 ml | D33: 0.8
A34: 87913 | C34: 25 x 40 ml | D34: 1
A35: 75229 | C35: 20X100 ML | D35: 2
A36: 80927 | B36: MIRAVIS DUO | C36: 20 X 50 ml | D36: 1
A37: 81359 | C37: 20X100 ML | D37: 2
A38: 85803 | B38: CARIAL FLEX 43WG | C38: 3x10x70 G | D38: 2.1
A39: 55458 | B39: FILIA 525 SE | C39: 20 X 50 ML | D39: 1
A40: 46420 | C40: 20 X 100 ML | D40: 2
...

Sheet Seed conv.
A1: Agi Code | B1: Name of Products | C1: Pack Size | D1: Conversion rate
A2: 4114195 | B2: ALO (PK 365) | C2: 10x10gm | D2: 0.1
A3: 294469 | B3: Altapati (Lal shak) | C3: 10 x 0.5 kg | D3: 5
A4: 4013509 | B4: Arshi (Cabbage) | C4: 10 x 10gm | D4: 0.1
A5: 4024886 | B5: Aruna | C5: 10 x 0.5 kg | D5: 5
A6: 4073384 | B6: Asha | C6: 10x10gm | D6: 0.1
A7: 4075097 | B7: Ava(EPTH 16) | C7: 10x5gm | D7: 0.05
A8: 4075098 | B8: Ava(EPTH 16) | C8: 10x10gm | D8: 0.1
A9: 4028654 | B9: Badsha (Water melon) | C9: 10 x 100 gm | D9: 1
A10: 4183807 | B10: BINA Dhan 17 (FS) | C10: 1 x 10 kg | D10: 10
A11: 4183809 | B11: BR 10 (FS) | C11: 1 x 10 kg | D11: 10
A12: 4190687 | B12: Bari Dhan 48 | C12: 10x3kg | D12: 30
A13: 4186483 | B13: BRRI Dhan 48 (FS) 1 x 10 kg | C13: 1 x 10 kg | D13: 10
... A188: 4197750 | B188: Zirashail (TLS) | C188: 15 x 2 kg | D188: 30
A189: Total
